Workbook

Sheet Participating entities
B2: S/No | C2: Entity Name | E2: AI COE Centre # | G2: FY 2026 | M2: FY 2027 | S2: FY 2028
G3: TOTAT RSEs* | H3: Qualifying RSEs approved by ECMF** | K3: Other RSEs | M3: TOTAT RSEs* | N3: Qualifying RSEs approved by ECMF** | Q3: Other RSEs | S3: TOTAT RSEs* | T3: Qualifying RSEs approved by ECMF** | W3: Other RSEs
H4: New Hirers | I4: Reskilled | J4: Upskilled | N4: New Hirers | O4: Reskilled | P4: Upskilled | T4: New Hirers | U4: Reskilled | V4: Upskilled
B5: 1 | C5: ST Engineering IHQ Pte Ltd | D5: GEC | G5: =SUM(H5:K7) -> 0 | M5: =SUM(N5:Q7) -> 0 | S5: =SUM(T5:W7) -> 0
D6: GTO
D7: IT
B8: =B5+1 -> 2 | C8: ST Engineering Advanced Networks & Sensors Pte Ltd | G8: =SUM(H8:K8) -> 0 | M8: =SUM(N8:Q8) -> 0 | S8: =SUM(T8:W8) -> 0
B9: =B8+1 -> 3 | C9: ST Engineering Digital System Pte Ltd | G9: =SUM(H9:K9) -> 0 | M9: =SUM(N9:Q9) -> 0 | S9: =SUM(T9:W9) -> 0
B10: =B9+1 -> 4 | C10: ST Engineering Geo-Insights Pte Ltd | G10: =SUM(H10:K10) -> 0 | M10: =SUM(N10:Q10) -> 0 | S10: =SUM(T10:W10) -> 0
B11: =B10+1 -> 5 | C11: ST Engineering Mission Software & Services Pte Ltd | G11: =SUM(H11:K11) -> 0 | M11: =SUM(N11:Q11) -> 0 | S11: =SUM(T11:W11) -> 0
B12: =B11+1 -> 6 | C12: ST Engineering Training & Simulation Systems Pte Ltd | G12: =SUM(H12:K12) -> 0 | M12: =SUM(N12:Q12) -> 0 | S12: =SUM(T12:W12) -> 0
B13: =B12+1 -> 7 | C13: ST Engineering Unmanned & Integrated Systems Pte Ltd | G13: =SUM(H13:K13) -> 0 | M13: =SUM(N13:Q13) -> 0 | S13: =SUM(T13:W13) -> 0
B14: =B13+1 -> 8 | C14: ST Engineering Advanced Material Engineering Pte Ltd | G14: =SUM(H14:K14) -> 0 | M14: =SUM(N14:Q14) -> 0 | S14: =SUM(T14:W14) -> 0
B15: =B14+1 -> 9 | C15: ST Engineering Land MRO & Services Pte Ltd | G15: =SUM(H15:K15) -> 0 | M15: =SUM(N15:Q15) -> 0 | S15: =SUM(T15:W15) -> 0
B16: =B15+1 -> 10 | C16: ST Engineering Land Systems Ltd | G16: =SUM(H16:K16) -> 0 | M16: =SUM(N16:Q16) -> 0 | S16: =SUM(T16:W16) -> 0
B17: =B16+1 -> 11 | C17: ST Engineering Autonomous Solutions Pte Ltd | G17: =SUM(H17:K17) -> 0 | M17: =SUM(N17:Q17) -> 0 | S17: =SUM(T17:W17) -> 0
B18: =B17+1 -> 12 | C18: ST Engineering Urban Solutions Ltd. | G18: =SUM(H18:K18) -> 0 | M18: =SUM(N18:Q18) -> 0 | S18: =SUM(T18:W18) -> 0
B19: =B18+1 -> 13 | C19: ST Engineering Mobility Services Pte Ltd | G19: =SUM(H19:K19) -> 0 | M19: =SUM(N19:Q19) -> 0 | S19: =SUM(T19:W19) -> 0
B20: =B19+1 -> 14 | C20: STA Inspection Pte Ltd | G20: =SUM(H20:K20) -> 0 | M20: =SUM(N20:Q20) -> 0 | S20: =SUM(T20:W20) -> 0
... B22: =B21+1 -> 16 | C22: ST Engineering Marine Ltd | G22: =SUM(H22:K22) -> 0 | M22: =SUM(N22:Q22) -> 0 | S22: =SUM(T22:W22) -> 0
B24: NOTES:
B25: * | C25: RSEs: Research Scientists and Engineers (RSEs).To qualify for the RIS(C) support, these RSEs must be local (i.e. citizens or permanent residents of Singapore)
B26: ** | C26: Engineering Competency Management Framework (ECMF) Committee chaired by Group CHRO and Group Chief Engineering Officer
G28: FY 2026 RSEs validated by: | M28: FY 2027 RSEs validated by: | S28: FY 2028 RSEs validated by:
H31: (Name) | N31: (Name) | T31: (Name)
H32: on behalf of ECMF | N32: on behalf of ECMF | T32: on behalf of ECMF
H34: Date | N34: Date | T34: Date

Sheet Time Sheet
B2: TIME SHEET
B3: To be completed on a monthly basis | G3: ST Engineering Advanced Networks & Sensors Pte Ltd
G4: (Name of Participating entity)
B5: Note:
B6: 1 Total hours spent for each month is capped at 100% on the basis of 8.8hours/ working day and respective number of working days in each month
B8: Qualifying Personnel refers to the following:
B9: - Grantee’s employees directly working on the Project but excludes employees undertaking support functions such as administration and finance. Both permanent employees and contract staff are qualifying personnel.
B10: - Undergraduate and post-graduate students from local Institutes of Higher Learning (IHLs) and secondees from related parties of the Grantee or public research institutes, only if –
C11: - They are directly working on the Project but excluding persons undertaking support functions such as administration and finance;
C12: - EDB is satisfied that their involvement has resulted in the building of local capability; and
C13: - The salaries of such persons are paid by the Grantee.
B14: - Employees of the Authorised Entity(s) directly working on the Project but excludes employees undertaking support functions such as administration and finance. Both permanent employees and contract staff are qualifying personnel.
B15: - “Locals” refers to qualifying personnel who are Singapore Citizens or Singapore Permanent Residents, while “Foreigners” refers to all other persons.
B17: PROJECT TEAM | N17: HOURS SPENT 1
B18: S/N | C18: Employee ID | D18: Name | E18: Local/ Foreigner | F18: Academic qualifications (Doctorate, Bachelor of Engineering, Masters of Science) | G18: Employee designation | H18: Validated by ECMF | I18: Confirm not enjoying any other government cash grant incentive | J18: Current AI Proficiency Level | K18: AI Capabilities* | L18: New Hirer/Upskilled/Reskilled | M18: Date of Completion for Upskilling or Reskilling | N18: Jan | O18: Feb | P18: Mar | Q18: Apr | R18: May | S18: Jun | T18: Jul | U18: Aug | V18: Sep | W18: Oct | X18: Nov | Y18: Dec | Z18: Total
B19: 1 | H19: FALSE | I19: FALSE | L19: Upskilled | M19: 46053 | W19: 40 | Z19: =SUM(N19:Y19) -> 40
B20: =B19+1 -> 2 | H20: FALSE | I20: FALSE | L20: New Hire | M20: 46053 | Z20: =SUM(N20:Y20) -> 0
B21: =B20+1 -> 3 | H21: FALSE | I21: FALSE | L21: Upskilled | Z21: =SUM(N21:Y21) -> 0
B22: =B21+1 -> 4 | H22: FALSE | I22: FALSE | L22: New Hire | Z22: =SUM(N22:Y22) -> 0
B23: =B22+1 -> 5 | H23: FALSE | I23: FALSE | L23: New Hire | Z23: =SUM(N23:Y23) -> 0
B24: =B23+1 -> 6 | H24: FALSE | I24: FALSE | L24: New Hire | Z24: =SUM(N24:Y24) -> 0
B25: =B24+1 -> 7 | H25: FALSE | I25: FALSE | L25: New Hire | Z25: =SUM(N25:Y25) -> 0
B26: =B25+1 -> 8 | H26: FALSE | I26: FALSE | L26: New Hire | Z26: =SUM(N26:Y26) -> 0
B27: =B26+1 -> 9 | H27: FALSE | I27: FALSE | L27: New Hire | Z27: =SUM(N27:Y27) -> 0
B28: =B27+1 -> 10 | H28: FALSE | I28: FALSE | L28: New Hire | Z28: =SUM(N28:Y28) -> 0
B29: =B28+1 -> 11 | H29: FALSE | I29: FALSE | L29: New Hire | Z29: =SUM(N29:Y29) -> 0
B30: =B29+1 -> 12 | H30: FALSE | I30: FALSE | L30: New Hire | Z30: =SUM(N30:Y30) -> 0
B31: =B30+1 -> 13 | H31: FALSE | I31: FALSE | L31: New Hire | Z31: =SUM(N31:Y31) -> 0
B32: =B31+1 -> 14 | H32: FALSE | I32: FALSE | L32: New Hire | Z32: =SUM(N32:Y32) -> 0
... B35: =B34+1 -> 17 | H35: FALSE | I35: FALSE | L35: New Hire | Z35: =SUM(N35:Y35) -> 0
B36: =B35+1 -> 18 | H36: FALSE | I36: FALSE | Z36: =SUM(N36:Y36) -> 0
B37: =B36+1 -> 19 | H37: FALSE | I37: FALSE | Z37: =SUM(N37:Y37) -> 0
B38: =B37+1 -> 20 | H38: FALSE | I38: FALSE | Z38: =SUM(N38:Y38) -> 0
B39: =B38+1 -> 21 | H39: FALSE | I39: FALSE | Z39: =SUM(N39:Y39) -> 0
B40: =B39+1 -> 22 | H40: FALSE | I40: FALSE | Z40: =SUM(N40:Y40) -> 0
B41: =B40+1 -> 23 | H41: FALSE | I41: FALSE | Z41: =SUM(N41:Y41) -> 0
B42: =B41+1 -> 24 | H42: FALSE | I42: FALSE | Z42: =SUM(N42:Y42) -> 0
B43: =B42+1 -> 25 | H43: FALSE | I43: FALSE | Z43: =SUM(N43:Y43) -> 0
B44: =B43+1 -> 26 | H44: FALSE | I44: FALSE | Z44: =SUM(N44:Y44) -> 0
B45: =B44+1 -> 27 | H45: FALSE | I45: FALSE | Z45: =SUM(N45:Y45) -> 0
...

Sheet Staff Costs
B2: STAFF COST
B3: To be completed on a monthly basis | F3: ='Time Sheet'!G3 -> ST Engineering Advanced Networks & Sensors Pte Ltd
F4: (Name of Participating entity)
B5: Note:
B6: 1 Total annual salary includes:
B7: - The qualifying cost for salary refers to basic monthly salaries of qualifying personnel with such salary of at least S$5,000.
B8: - The qualifying costs for basic monthly salaries shall be capped at S$20,000 per calendar month per qualifying personnel.
B9: - All other costs (e.g. training costs, bonuses and allowances including annual wage supplements, and employer's CPF contributions, Cost of Living Allowance (COLA) & Airfare) are not qualifying.
B11: 2 Adjustments are made to exclude out weekends in computing total employment hours for the year
B13: HUMAN RESOURCES | I13: Actual monthly salary per IR8A | J13: Total qualifying annual salary1 | K13: Date join | L13: Date left | M13: Total hours in employment (not adjusted for leave/PHs) 2 | N13: Time spent on project (Hours) | O13: % of time spent on Project | P13: Staff Cost for RISC Claims
B14: S/N | C14: Employee ID | D14: Name | E14: Local/ Foreigner | F14: Academic qualifications (Doctorate, Bachelor of Engineering, Masters of Science) | G14: Designations | H14: New Hirer/Upskilled/Reskilled | I14: [A] | J14: [B] | K14: [C1] | L14: [C2] | M14: [D1] = [C2 - C1] * 8.8 Hrs | N14: [D2] | O14: [D3] = [D2/D1] | P14: [E] = [B * D3]
B15: 1 | C15: ='Time Sheet'!C19 -> 0 | D15: ='Time Sheet'!D19 -> 0 | E15: ='Time Sheet'!E19 -> 0 | F15: ='Time Sheet'!F19 -> 0 | G15: ='Time Sheet'!G19 -> 0 | H15: ='Time Sheet'!L19 -> Upskilled | I15: 10000 | J15: =IFERROR(IF(I15<5000,"N/A",MIN(I15,20000)),"N/A") -> 10000 | K15: 46023 | L15: 46387 | M15: =(NETWORKDAYS(K15,L15))*8.8 -> 2296.8 | N15: =IF(H15="New Hire","N/A",'Time Sheet'!Z19) -> 40 | O15: =IF(H15="New Hire",100%,N15/M15) -> 0.017415535 | P15: =J15*O15 -> 174.15535
B16: =B15+1 -> 2 | C16: ='Time Sheet'!C20 -> 0 | D16: ='Time Sheet'!D20 -> 0 | E16: ='Time Sheet'!E20 -> 0 | F16: ='Time Sheet'!F20 -> 0 | G16: ='Time Sheet'!G20 -> 0 | H16: ='Time Sheet'!L20 -> New Hire | I16: 10000 | J16: =IFERROR(IF(I16<5000,"N/A",MIN(I16,20000)),"N/A") -> 10000 | K16: 46023 | L16: 46326 | M16: =(NETWORKDAYS(K16,L16))*8.8 -> 1909.6 | N16: =IF(H16="New Hire","N/A",'Time Sheet'!Z20) -> N/A | O16: =IF(H16="New Hire",100%,N16/M16) -> 1 | P16: =J16*O16 -> 10000
B17: =B16+1 -> 3 | C17: ='Time Sheet'!C21 -> 0 | D17: ='Time Sheet'!D21 -> 0 | E17: ='Time Sheet'!E21 -> 0 | F17: ='Time Sheet'!F21 -> 0 | G17: ='Time Sheet'!G21 -> 0 | H17: ='Time Sheet'!L21 -> Upskilled | I17: 10000 | J17: =IFERROR(IF(I17<5000,"N/A",MIN(I17,20000)),"N/A") -> 10000 | K17: 46023 | L17: 46326 | M17: =(NETWORKDAYS(K17,L17))*8.8 -> 1909.6 | N17: =IF(H17="New Hire","N/A",'Time Sheet'!Z21) -> 0 | O17: =IF(H17="New Hire",100%,N17/M17) -> 0 | P17: =J17*O17 -> 0
B18: =B17+1 -> 4 | C18: ='Time Sheet'!C22 -> 0 | D18: ='Time Sheet'!D22 -> 0 | E18: ='Time Sheet'!E22 -> 0 | F18: ='Time Sheet'!F22 -> 0 | G18: ='Time Sheet'!G22 -> 0 | H18: ='Time Sheet'!L22 -> New Hire | I18: 10000 | J18: =IFERROR(IF(I18<5000,"N/A",MIN(I18,20000)),"N/A") -> 10000 | K18: 46023 | L18: 46326 | M18: =(NETWORKDAYS(K18,L18))*8.8 -> 1909.6 | N18: =IF(H18="New Hire","N/A",'Time Sheet'!Z22) -> N/A | O18: =IF(H18="New Hire",100%,N18/M18) -> 1 | P18: =J18*O18 -> 10000
B19: =B18+1 -> 5 | C19: ='Time Sheet'!C23 -> 0 | D19: ='Time Sheet'!D23 -> 0 | E19: ='Time Sheet'!E23 -> 0 | F19: ='Time Sheet'!F23 -> 0 | G19: ='Time Sheet'!G23 -> 0 | H19: ='Time Sheet'!L23 -> New Hire | I19: 10000 | J19: =IFERROR(IF(I19<5000,"N/A",MIN(I19,20000)),"N/A") -> 10000 | K19: 46023 | L19: 46326 | M19: =(NETWORKDAYS(K19,L19))*8.8 -> 1909.6 | N19: =IF(H19="New Hire","N/A",'Time Sheet'!Z23) -> N/A | O19: =IF(H19="New Hire",100%,N19/M19) -> 1 | P19: =J19*O19 -> 10000
B20: =B19+1 -> 6 | C20: ='Time Sheet'!C24 -> 0 | D20: ='Time Sheet'!D24 -> 0 | E20: ='Time Sheet'!E24 -> 0 | F20: ='Time Sheet'!F24 -> 0 | G20: ='Time Sheet'!G24 -> 0 | H20: ='Time Sheet'!L24 -> New Hire | I20: 10000 | J20: =IFERROR(IF(I20<5000,"N/A",MIN(I20,20000)),"N/A") -> 10000 | K20: 46023 | L20: 46326 | M20: =(NETWORKDAYS(K20,L20))*8.8 -> 1909.6 | N20: =IF(H20="New Hire","N/A",'Time Sheet'!Z24) -> N/A | O20: =IF(H20="New Hire",100%,N20/M20) -> 1 | P20: =J20*O20 -> 10000
B21: =B20+1 -> 7 | C21: ='Time Sheet'!C25 -> 0 | D21: ='Time Sheet'!D25 -> 0 | E21: ='Time Sheet'!E25 -> 0 | F21: ='Time Sheet'!F25 -> 0 | G21: ='Time Sheet'!G25 -> 0 | H21: ='Time Sheet'!L25 -> New Hire | I21: 10000 | J21: =IFERROR(IF(I21<5000,"N/A",MIN(I21,20000)),"N/A") -> 10000 | K21: 46023 | L21: 46326 | M21: =(NETWORKDAYS(K21,L21))*8.8 -> 1909.6 | N21: =IF(H21="New Hire","N/A",'Time Sheet'!Z25) -> N/A | O21: =IF(H21="New Hire",100%,N21/M21) -> 1 | P21: =J21*O21 -> 10000
B22: =B21+1 -> 8 | C22: ='Time Sheet'!C26 -> 0 | D22: ='Time Sheet'!D26 -> 0 | E22: ='Time Sheet'!E26 -> 0 | F22: ='Time Sheet'!F26 -> 0 | G22: ='Time Sheet'!G26 -> 0 | H22: ='Time Sheet'!L26 -> New Hire | I22: 10000 | J22: =IFERROR(IF(I22<5000,"N/A",MIN(I22,20000)),"N/A") -> 10000 | K22: 46023 | L22: 46326 | M22: =(NETWORKDAYS(K22,L22))*8.8 -> 1909.6 | N22: =IF(H22="New Hire","N/A",'Time Sheet'!Z26) -> N/A | O22: =IF(H22="New Hire",100%,N22/M22) -> 1 | P22: =J22*O22 -> 10000
B23: =B22+1 -> 9 | C23: ='Time Sheet'!C27 -> 0 | D23: ='Time Sheet'!D27 -> 0 | E23: ='Time Sheet'!E27 -> 0 | F23: ='Time Sheet'!F27 -> 0 | G23: ='Time Sheet'!G27 -> 0 | H23: ='Time Sheet'!L27 -> New Hire | I23: 10000 | J23: =IFERROR(IF(I23<5000,"N/A",MIN(I23,20000)),"N/A") -> 10000 | K23: 46023 | L23: 46326 | M23: =(NETWORKDAYS(K23,L23))*8.8 -> 1909.6 | N23: =IF(H23="New Hire","N/A",'Time Sheet'!Z27) -> N/A | O23: =IF(H23="New Hire",100%,N23/M23) -> 1 | P23: =J23*O23 -> 10000
B24: =B23+1 -> 10 | C24: ='Time Sheet'!C28 -> 0 | D24: ='Time Sheet'!D28 -> 0 | E24: ='Time Sheet'!E28 -> 0 | F24: ='Time Sheet'!F28 -> 0 | G24: ='Time Sheet'!G28 -> 0 | H24: ='Time Sheet'!L28 -> New Hire | I24: 10000 | J24: =IFERROR(IF(I24<5000,"N/A",MIN(I24,20000)),"N/A") -> 10000 | K24: 46023 | L24: 46326 | M24: =(NETWORKDAYS(K24,L24))*8.8 -> 1909.6 | N24: =IF(H24="New Hire","N/A",'Time Sheet'!Z28) -> N/A | O24: =IF(H24="New Hire",100%,N24/M24) -> 1 | P24: =J24*O24 -> 10000
B25: =B24+1 -> 11 | C25: ='Time Sheet'!C29 -> 0 | D25: ='Time Sheet'!D29 -> 0 | E25: ='Time Sheet'!E29 -> 0 | F25: ='Time Sheet'!F29 -> 0 | G25: ='Time Sheet'!G29 -> 0 | H25: ='Time Sheet'!L29 -> New Hire | I25: 10000 | J25: =IFERROR(IF(I25<5000,"N/A",MIN(I25,20000)),"N/A") -> 10000 | K25: 46023 | L25: 46326 | M25: =(NETWORKDAYS(K25,L25))*8.8 -> 1909.6 | N25: =IF(H25="New Hire","N/A",'Time Sheet'!Z29) -> N/A | O25: =IF(H25="New Hire",100%,N25/M25) -> 1 | P25: =J25*O25 -> 10000
B26: =B25+1 -> 12 | C26: ='Time Sheet'!C30 -> 0 | D26: ='Time Sheet'!D30 -> 0 | E26: ='Time Sheet'!E30 -> 0 | F26: ='Time Sheet'!F30 -> 0 | G26: ='Time Sheet'!G30 -> 0 | H26: ='Time Sheet'!L30 -> New Hire | I26: 10000 | J26: =IFERROR(IF(I26<5000,"N/A",MIN(I26,20000)),"N/A") -> 10000 | K26: 46023 | L26: 46326 | M26: =(NETWORKDAYS(K26,L26))*8.8 -> 1909.6 | N26: =IF(H26="New Hire","N/A",'Time Sheet'!Z30) -> N/A | O26: =IF(H26="New Hire",100%,N26/M26) -> 1 | P26: =J26*O26 -> 10000
B27: =B26+1 -> 13 | C27: ='Time Sheet'!C31 -> 0 | D27: ='Time Sheet'!D31 -> 0 | E27: ='Time Sheet'!E31 -> 0 | F27: ='Time Sheet'!F31 -> 0 | G27: ='Time Sheet'!G31 -> 0 | H27: ='Time Sheet'!L31 -> New Hire | I27: 10000 | J27: =IFERROR(IF(I27<5000,"N/A",MIN(I27,20000)),"N/A") -> 10000 | K27: 46023 | L27: 46326 | M27: =(NETWORKDAYS(K27,L27))*8.8 -> 1909.6 | N27: =IF(H27="New Hire","N/A",'Time Sheet'!Z31) -> N/A | O27: =IF(H27="New Hire",100%,N27/M27) -> 1 | P27: =J27*O27 -> 10000
... B45: =B44+1 -> 31 | C45: ='Time Sheet'!C49 -> 0 | D45: ='Time Sheet'!D49 -> 0 | E45: ='Time Sheet'!E49 -> 0 | F45: ='Time Sheet'!F49 -> 0 | G45: ='Time Sheet'!G49 -> 0 | H45: ='Time Sheet'!L49 -> 0 | I45: 10000 | J45: =IFERROR(IF(I45<5000,"N/A",MIN(I45,20000)),"N/A") -> 10000 | K45: 46023 | L45: 46326 | M45: =(NETWORKDAYS(K45,L45))*8.8 -> 1909.6 | N45: =IF(H45="New Hire","N/A",'Time Sheet'!Z49) -> 0 | O45: =IF(H45="New Hire",100%,N45/M45) -> 0 | P45: =J45*O45 -> 0
B46: =B45+1 -> 32 | C46: ='Time Sheet'!C50 -> 0 | D46: ='Time Sheet'!D50 -> 0 | E46: ='Time Sheet'!E50 -> 0 | F46: ='Time Sheet'!F50 -> 0 | G46: ='Time Sheet'!G50 -> 0 | H46: ='Time Sheet'!L50 -> 0 | I46: 10000 | J46: =IFERROR(IF(I46<5000,"N/A",MIN(I46,20000)),"N/A") -> 10000 | M46: =(NETWORKDAYS(K46,L46))*8.8 -> 0 | N46: =IF(H46="New Hire","N/A",'Time Sheet'!Z50) -> 0 | O46: =IF(H46="New Hire",100%,N46/M46) -> #DIV/0! | P46: =J46*O46 -> #DIV/0!
B47: =B46+1 -> 33 | C47: ='Time Sheet'!C51 -> 0 | D47: ='Time Sheet'!D51 -> 0 | E47: ='Time Sheet'!E51 -> 0 | F47: ='Time Sheet'!F51 -> 0 | G47: ='Time Sheet'!G51 -> 0 | H47: ='Time Sheet'!L51 -> 0 | I47: 10000 | J47: =IFERROR(IF(I47<5000,"N/A",MIN(I47,20000)),"N/A") -> 10000 | M47: =(NETWORKDAYS(K47,L47))*8.8 -> 0 | N47: =IF(H47="New Hire","N/A",'Time Sheet'!Z51) -> 0 | O47: =IF(H47="New Hire",100%,N47/M47) -> #DIV/0! | P47: =J47*O47 -> #DIV/0!
B48: =B47+1 -> 34 | C48: ='Time Sheet'!C52 -> 0 | D48: ='Time Sheet'!D52 -> 0 | E48: ='Time Sheet'!E52 -> 0 | F48: ='Time Sheet'!F52 -> 0 | G48: ='Time Sheet'!G52 -> 0 | H48: ='Time Sheet'!L52 -> 0 | J48: =IFERROR(IF(I48<5000,"N/A",MIN(I48,20000)),"N/A") -> N/A | M48: =(NETWORKDAYS(K48,L48))*8.8 -> 0 | N48: =IF(H48="New Hire","N/A",'Time Sheet'!Z52) -> 0 | O48: =IF(H48="New Hire",100%,N48/M48) -> #DIV/0! | P48: =J48*O48 -> #VALUE!
B49: =B48+1 -> 35 | C49: ='Time Sheet'!C53 -> 0 | D49: ='Time Sheet'!D53 -> 0 | E49: ='Time Sheet'!E53 -> 0 | F49: ='Time Sheet'!F53 -> 0 | G49: ='Time Sheet'!G53 -> 0 | H49: ='Time Sheet'!L53 -> 0 | J49: =IFERROR(IF(I49<5000,"N/A",MIN(I49,20000)),"N/A") -> N/A | M49: =(NETWORKDAYS(K49,L49))*8.8 -> 0 | N49: =IF(H49="New Hire","N/A",'Time Sheet'!Z53) -> 0 | O49: =IF(H49="New Hire",100%,N49/M49) -> #DIV/0! | P49: =J49*O49 -> #VALUE!
B50: =B49+1 -> 36 | C50: ='Time Sheet'!C54 -> 0 | D50: ='Time Sheet'!D54 -> 0 | E50: ='Time Sheet'!E54 -> 0 | F50: ='Time Sheet'!F54 -> 0 | G50: ='Time Sheet'!G54 -> 0 | H50: ='Time Sheet'!L54 -> 0 | J50: =IFERROR(IF(I50<5000,"N/A",MIN(I50,20000)),"N/A") -> N/A | M50: =(NETWORKDAYS(K50,L50))*8.8 -> 0 | N50: =IF(H50="New Hire","N/A",'Time Sheet'!Z54) -> 0 | O50: =IF(H50="New Hire",100%,N50/M50) -> #DIV/0! | P50: =J50*O50 -> #VALUE!
B51: =B50+1 -> 37 | C51: ='Time Sheet'!C55 -> 0 | D51: ='Time Sheet'!D55 -> 0 | E51: ='Time Sheet'!E55 -> 0 | F51: ='Time Sheet'!F55 -> 0 | G51: ='Time Sheet'!G55 -> 0 | H51: ='Time Sheet'!L55 -> 0 | J51: =IFERROR(IF(I51<5000,"N/A",MIN(I51,20000)),"N/A") -> N/A | M51: =(NETWORKDAYS(K51,L51))*8.8 -> 0 | N51: =IF(H51="New Hire","N/A",'Time Sheet'!Z55) -> 0 | O51: =IF(H51="New Hire",100%,N51/M51) -> #DIV/0! | P51: =J51*O51 -> #VALUE!
B52: =B51+1 -> 38 | C52: ='Time Sheet'!C56 -> 0 | D52: ='Time Sheet'!D56 -> 0 | E52: ='Time Sheet'!E56 -> 0 | F52: ='Time Sheet'!F56 -> 0 | G52: ='Time Sheet'!G56 -> 0 | H52: ='Time Sheet'!L56 -> 0 | J52: =IFERROR(IF(I52<5000,"N/A",MIN(I52,20000)),"N/A") -> N/A | M52: =(NETWORKDAYS(K52,L52))*8.8 -> 0 | N52: =IF(H52="New Hire","N/A",'Time Sheet'!Z56) -> 0 | O52: =IF(H52="New Hire",100%,N52/M52) -> #DIV/0! | P52: =J52*O52 -> #VALUE!
B53: =B52+1 -> 39 | C53: ='Time Sheet'!C57 -> 0 | D53: ='Time Sheet'!D57 -> 0 | E53: ='Time Sheet'!E57 -> 0 | F53: ='Time Sheet'!F57 -> 0 | G53: ='Time Sheet'!G57 -> 0 | H53: ='Time Sheet'!L57 -> 0 | J53: =IFERROR(IF(I53<5000,"N/A",MIN(I53,20000)),"N/A") -> N/A | M53: =(NETWORKDAYS(K53,L53))*8.8 -> 0 | N53: =IF(H53="New Hire","N/A",'Time Sheet'!Z57) -> 0 | O53: =IF(H53="New Hire",100%,N53/M53) -> #DIV/0! | P53: =J53*O53 -> #VALUE!
B54: =B53+1 -> 40 | C54: ='Time Sheet'!C58 -> 0 | D54: ='Time Sheet'!D58 -> 0 | E54: ='Time Sheet'!E58 -> 0 | F54: ='Time Sheet'!F58 -> 0 | G54: ='Time Sheet'!G58 -> 0 | H54: ='Time Sheet'!L58 -> 0 | J54: =IFERROR(IF(I54<5000,"N/A",MIN(I54,20000)),"N/A") -> N/A | M54: =(NETWORKDAYS(K54,L54))*8.8 -> 0 | N54: =IF(H54="New Hire","N/A",'Time Sheet'!Z58) -> 0 | O54: =IF(H54="New Hire",100%,N54/M54) -> #DIV/0! | P54: =J54*O54 -> #VALUE!
B55: =B54+1 -> 41 | C55: ='Time Sheet'!C59 -> 0 | D55: ='Time Sheet'!D59 -> 0 | E55: ='Time Sheet'!E59 -> 0 | F55: ='Time Sheet'!F59 -> 0 | G55: ='Time Sheet'!G59 -> 0 | H55: ='Time Sheet'!L59 -> 0 | J55: =IFERROR(IF(I55<5000,"N/A",MIN(I55,20000)),"N/A") -> N/A | M55: =(NETWORKDAYS(K55,L55))*8.8 -> 0 | N55: =IF(H55="New Hire","N/A",'Time Sheet'!Z59) -> 0 | O55: =IF(H55="New Hire",100%,N55/M55) -> #DIV/0! | P55: =J55*O55 -> #VALUE!
B56: =B55+1 -> 42 | C56: ='Time Sheet'!C60 -> 0 | D56: ='Time Sheet'!D60 -> 0 | E56: ='Time Sheet'!E60 -> 0 | F56: ='Time Sheet'!F60 -> 0 | G56: ='Time Sheet'!G60 -> 0 | H56: ='Time Sheet'!L60 -> 0 | J56: =IFERROR(IF(I56<5000,"N/A",MIN(I56,20000)),"N/A") -> N/A | M56: =(NETWORKDAYS(K56,L56))*8.8 -> 0 | N56: =IF(H56="New Hire","N/A",'Time Sheet'!Z60) -> 0 | O56: =IF(H56="New Hire",100%,N56/M56) -> #DIV/0! | P56: =J56*O56 -> #VALUE!
B57: =B56+1 -> 43 | C57: ='Time Sheet'!C61 -> 0 | D57: ='Time Sheet'!D61 -> 0 | E57: ='Time Sheet'!E61 -> 0 | F57: ='Time Sheet'!F61 -> 0 | G57: ='Time Sheet'!G61 -> 0 | H57: ='Time Sheet'!L61 -> 0 | J57: =IFERROR(IF(I57<5000,"N/A",MIN(I57,20000)),"N/A") -> N/A | M57: =(NETWORKDAYS(K57,L57))*8.8 -> 0 | N57: =IF(H57="New Hire","N/A",'Time Sheet'!Z61) -> 0 | O57: =IF(H57="New Hire",100%,N57/M57) -> #DIV/0! | P57: =J57*O57 -> #VALUE!
B58: =B57+1 -> 44 | C58: ='Time Sheet'!C62 -> 0 | D58: ='Time Sheet'!D62 -> 0 | E58: ='Time Sheet'!E62 -> 0 | F58: ='Time Sheet'!F62 -> 0 | G58: ='Time Sheet'!G62 -> 0 | H58: ='Time Sheet'!L62 -> 0 | J58: =IFERROR(IF(I58<5000,"N/A",MIN(I58,20000)),"N/A") -> N/A | M58: =(NETWORKDAYS(K58,L58))*8.8 -> 0 | N58: =IF(H58="New Hire","N/A",'Time Sheet'!Z62) -> 0 | O58: =IF(H58="New Hire",100%,N58/M58) -> #DIV/0! | P58: =J58*O58 -> #VALUE!
B59: =B58+1 -> 45 | C59: ='Time Sheet'!C63 -> 0 | D59: ='Time Sheet'!D63 -> 0 | E59: ='Time Sheet'!E63 -> 0 | F59: ='Time Sheet'!F63 -> 0 | G59: ='Time Sheet'!G63 -> 0 | H59: ='Time Sheet'!L63 -> 0 | J59: =IFERROR(IF(I59<5000,"N/A",MIN(I59,20000)),"N/A") -> N/A | M59: =(NETWORKDAYS(K59,L59))*8.8 -> 0 | N59: =IF(H59="New Hire","N/A",'Time Sheet'!Z63) -> 0 | O59: =IF(H59="New Hire",100%,N59/M59) -> #DIV/0! | P59: =J59*O59 -> #VALUE!
... B64: =B63+1 -> 50 | C64: ='Time Sheet'!C68 -> 0 | D64: ='Time Sheet'!D68 -> 0 | E64: ='Time Sheet'!E68 -> 0 | F64: ='Time Sheet'!F68 -> 0 | G64: ='Time Sheet'!G68 -> 0 | H64: ='Time Sheet'!L68 -> 0 | J64: =IFERROR(IF(I64<5000,"N/A",MIN(I64,20000)),"N/A") -> N/A | M64: =(NETWORKDAYS(K64,L64))*8.8 -> 0 | N64: =IF(H64="New Hire","N/A",'Time Sheet'!Z68) -> 0 | O64: =IF(H64="New Hire",100%,N64/M64) -> #DIV/0! | P64: =J64*O64 -> #VALUE!
...

Sheet List
B2: Participating Entities | C2: Current AI Proficiency Level | D2: AI Capabilities* | E2: New Hirer/Upskilled/ Reskilled
B3: ST Engineering IHQ Pte Ltd | C3: PL1 | D3: AI For Smart City Operations | E3: New Hire
B4: ST Engineering Advanced Networks & Sensors Pte Ltd | C4: PL2 | D4: Next Generation AI (including Physical AI, Multi-Agent AI, and Quantum with AI) | E4: Upskilled
B5: ST Engineering Digital System Pte Ltd | C5: PL3 | D5: Agentic Platforms | E5: Reskilled
B6: ST Engineering Geo-Insights Pte Ltd | C6: PL4 | D6: AI Trust, Safety and Governance
B7: ST Engineering Mission Software & Services Pte Ltd | C7: PL5
B8: ST Engineering Training & Simulation Systems Pte Ltd
B9: ST Engineering Unmanned & Integrated Systems Pte Ltd
B10: ST Engineering Advanced Material Engineering Pte Ltd
B11: ST Engineering Land MRO & Services Pte Ltd
B12: ST Engineering Land Systems Ltd
B13: ST Engineering Autonomous Solutions Pte Ltd
B14: ST Engineering Urban Solutions Ltd.
B15: ST Engineering Mobility Services Pte Ltd
B16: STA Inspection Pte Ltd
B17: ST Engineering Aerospace Ltd
B18: ST Engineering Marine Ltd
